TemperatureEstimator - ERROR - Exception occurred
Traceback (most recent call last):
  File "c:\Users\ZRasheed\Desktop\Pekka Task\Updated auto code project\facial based attendance\Temp_screening.py", line 68, in main
    te = TemperatureEstimator("path_to_your_pretrained_model")
         ^^^^^^^^^^^^^^^^^^^^^^^^^^^^^^^^^^^^^^^^^^^^^^^^^^^^^
  File "c:\Users\ZRasheed\Desktop\Pekka Task\Updated auto code project\facial based attendance\Temp_screening.py", line 20, in __init__
    self.model = keras.models.load_model(model_path)
                 ^^^^^^^^^^^^^^^^^^^^^^^^^^^^^^^^^^^
  File "C:\Users\ZRasheed\AppData\Local\Packages\PythonSoftwareFoundation.Python.3.11_qbz5n2kfra8p0\LocalCache\local-packages\Python311\site-packages\keras\src\saving\saving_api.py", line 262, in load_model
    return legacy_sm_saving_lib.load_model(
           ^^^^^^^^^^^^^^^^^^^^^^^^^^^^^^^^
  File "C:\Users\ZRasheed\AppData\Local\Packages\PythonSoftwareFoundation.Python.3.11_qbz5n2kfra8p0\LocalCache\local-packages\Python311\site-packages\keras\src\utils\traceback_utils.py", line 70, in error_handler
    raise e.with_traceback(filtered_tb) from None
  File "C:\Users\ZRasheed\AppData\Local\Packages\PythonSoftwareFoundation.Python.3.11_qbz5n2kfra8p0\LocalCache\local-packages\Python311\site-packages\keras\src\saving\legacy\save.py", line 234, in load_model
    raise IOError(
OSError: No file or directory found at path_to_your_pretrained_model
